Workbook
Name Slicer_Gender: #N/A
Name Slicer_Payment_Status: #N/A

Sheet Data
A1: ID | B1: Names | C1: Gender | D1: Salutation | E1: Proper Name | F1: First Name | G1: Last Name | H1: Region | I1: PassingYear | J1: Price | K1: Payment Status | L1: TotalPoints | M1: Signup Device | N1: Streak | O1: Course Name | P1: DegreeCategories - DegreeCategoryId → Name
A2: 64576 | B2: Aarav Dutta | C2: Male | D2: =IF(C2="Male","Mr.","Mrs.") -> Mr. | E2: =_xlfn.CONCAT(D2,B2) -> Mr.Aarav Dutta | F2: =LEFT(B2,FIND(" ",B2)-1) -> Aarav | G2: =MID(B2,FIND(" ",B2)+1,LEN(B2)) -> Dutta | H2: West | I2: 2022 | J2: {=_xlfn.SWITCH(TRUE,H2="North",10000,H2="South",10000,5000)} -> 5000 | K2: Pending | L2: 108 | M2: Mobile | N2: 7 | O2: Competitive Coding | P2: BE / BTech - Non CS / IT
A3: 64578 | B3: Dev Joshi | C3: Male | D3: =IF(C3="Male","Mr.","Mrs.") -> Mr. | E3: =_xlfn.CONCAT(D3,B3) -> Mr.Dev Joshi | F3: =LEFT(B3,FIND(" ",B3)-1) -> Dev | G3: =MID(B3,FIND(" ",B3)+1,LEN(B3)) -> Joshi | H3: North | I3: 2020 | J3: {=_xlfn.SWITCH(TRUE,H3="North",10000,H3="South",10000,5000)} -> 10000 | K3: Completed | L3: 23879 | M3: Mobile | N3: 40 | O3: Kickstarting Web Dev | P3: BCA / MCA
A4: 64580 | B4: Manya Sharma | C4: Male | D4: =IF(C4="Male","Mr.","Mrs.") -> Mr. | E4: =_xlfn.CONCAT(D4,B4) -> Mr.Manya Sharma | F4: =LEFT(B4,FIND(" ",B4)-1) -> Manya | G4: =MID(B4,FIND(" ",B4)+1,LEN(B4)) -> Sharma | H4: West | I4: 2022 | J4: {=_xlfn.SWITCH(TRUE,H4="North",10000,H4="South",10000,5000)} -> 5000 | K4: Completed | L4: 9454 | M4: Web | N4: 22 | O4: Competitive Coding | P4: BE / BTech - CS / IT
A5: 64582 | B5: Samarth Iyer | C5: Male | D5: =IF(C5="Male","Mr.","Mrs.") -> Mr. | E5: =_xlfn.CONCAT(D5,B5) -> Mr.Samarth Iyer | F5: =LEFT(B5,FIND(" ",B5)-1) -> Samarth | G5: =MID(B5,FIND(" ",B5)+1,LEN(B5)) -> Iyer | H5: South | I5: 2019 | J5: {=_xlfn.SWITCH(TRUE,H5="North",10000,H5="South",10000,5000)} -> 10000 | K5: Pending | L5: 0 | M5: Web | N5: 76 | O5: Kickstarting Web Dev | P5: BCA / MCA
A6: 64583 | B6: Mishka Jain | C6: Female | D6: =IF(C6="Male","Mr.","Mrs.") -> Mrs. | E6: =_xlfn.CONCAT(D6,B6) -> Mrs.Mishka Jain | F6: =LEFT(B6,FIND(" ",B6)-1) -> Mishka | G6: =MID(B6,FIND(" ",B6)+1,LEN(B6)) -> Jain | H6: North | I6: 2024 | J6: {=_xlfn.SWITCH(TRUE,H6="North",10000,H6="South",10000,5000)} -> 10000 | K6: Pending | L6: 0 | M6: Web | N6: 19 | O6: Kickstarting Web Dev | P6: BCA / MCA
A7: 64584 | B7: Ira Naidu | C7: Female | D7: =IF(C7="Male","Mr.","Mrs.") -> Mrs. | E7: =_xlfn.CONCAT(D7,B7) -> Mrs.Ira Naidu | F7: =LEFT(B7,FIND(" ",B7)-1) -> Ira | G7: =MID(B7,FIND(" ",B7)+1,LEN(B7)) -> Naidu | H7: West | I7: 2023 | J7: {=_xlfn.SWITCH(TRUE,H7="North",10000,H7="South",10000,5000)} -> 5000 | K7: Payment in Process | L7: 0 | M7: Mobile | N7: 2 | O7: Kickstarting Web Dev | P7: Non-Coding, Non Engineering
A8: 64585 | B8: Aaryan Sinha | C8: Male | D8: =IF(C8="Male","Mr.","Mrs.") -> Mr. | E8: =_xlfn.CONCAT(D8,B8) -> Mr.Aaryan Sinha | F8: =LEFT(B8,FIND(" ",B8)-1) -> Aaryan | G8: =MID(B8,FIND(" ",B8)+1,LEN(B8)) -> Sinha | H8: South | I8: 2016 | J8: {=_xlfn.SWITCH(TRUE,H8="North",10000,H8="South",10000,5000)} -> 10000 | K8: Completed | L8: 1618 | M8: Web | N8: 76 | O8: Data Structure and Algorithms | P8: Non-Coding, Non Engineering
A9: 64586 | B9: Arnav Nair | C9: Male | D9: =IF(C9="Male","Mr.","Mrs.") -> Mr. | E9: =_xlfn.CONCAT(D9,B9) -> Mr.Arnav Nair | F9: =LEFT(B9,FIND(" ",B9)-1) -> Arnav | G9: =MID(B9,FIND(" ",B9)+1,LEN(B9)) -> Nair | H9: North | I9: 2018 | J9: {=_xlfn.SWITCH(TRUE,H9="North",10000,H9="South",10000,5000)} -> 10000 | K9: Completed | L9: 1698 | M9: Web | N9: 63 | O9: Competitive Coding | P9: BE / BTech - CS / IT
A10: 64588 | B10: Lavanya Pillai | C10: Female | D10: =IF(C10="Male","Mr.","Mrs.") -> Mrs. | E10: =_xlfn.CONCAT(D10,B10) -> Mrs.Lavanya Pillai | F10: =LEFT(B10,FIND(" ",B10)-1) -> Lavanya | G10: =MID(B10,FIND(" ",B10)+1,LEN(B10)) -> Pillai | H10: South | I10: 2025 | J10: {=_xlfn.SWITCH(TRUE,H10="North",10000,H10="South",10000,5000)} -> 10000 | K10: Completed | L10: 33696 | M10: Web | N10: 59 | O10: Kickstarting Web Dev | P10: BE / BTech - CS / IT
A11: 64595 | B11: Aaryan Mehta | C11: Male | D11: =IF(C11="Male","Mr.","Mrs.") -> Mr. | E11: =_xlfn.CONCAT(D11,B11) -> Mr.Aaryan Mehta | F11: =LEFT(B11,FIND(" ",B11)-1) -> Aaryan | G11: =MID(B11,FIND(" ",B11)+1,LEN(B11)) -> Mehta | H11: East | I11: 2018 | J11: {=_xlfn.SWITCH(TRUE,H11="North",10000,H11="South",10000,5000)} -> 5000 | K11: Pending | L11: 1026 | M11: Web | N11: 43 | O11: Competitive Coding | P11: Non-Coding, Non Engineering
A12: 64596 | B12: Diya Gupta | C12: Female | D12: =IF(C12="Male","Mr.","Mrs.") -> Mrs. | E12: =_xlfn.CONCAT(D12,B12) -> Mrs.Diya Gupta | F12: =LEFT(B12,FIND(" ",B12)-1) -> Diya | G12: =MID(B12,FIND(" ",B12)+1,LEN(B12)) -> Gupta | H12: West | I12: 2016 | J12: {=_xlfn.SWITCH(TRUE,H12="North",10000,H12="South",10000,5000)} -> 5000 | K12: Payment in Process | L12: 0 | M12: Mobile | N12: 40 | O12: Data Structure and Algorithms | P12: BE / BTech - CS / IT
A13: 64599 | B13: Kian Mishra | C13: Male | D13: =IF(C13="Male","Mr.","Mrs.") -> Mr. | E13: =_xlfn.CONCAT(D13,B13) -> Mr.Kian Mishra | F13: =LEFT(B13,FIND(" ",B13)-1) -> Kian | G13: =MID(B13,FIND(" ",B13)+1,LEN(B13)) -> Mishra | H13: North | I13: 2025 | J13: {=_xlfn.SWITCH(TRUE,H13="North",10000,H13="South",10000,5000)} -> 10000 | K13: Pending | L13: 0 | M13: Web | N13: 27 | O13: Kickstarting Web Dev | P13: Non-Coding, Non Engineering
A14: 64600 | B14: Ayaan Kapoor | C14: Male | D14: =IF(C14="Male","Mr.","Mrs.") -> Mr. | E14: =_xlfn.CONCAT(D14,B14) -> Mr.Ayaan Kapoor | F14: =LEFT(B14,FIND(" ",B14)-1) -> Ayaan | G14: =MID(B14,FIND(" ",B14)+1,LEN(B14)) -> Kapoor | H14: North | I14: 2024 | J14: {=_xlfn.SWITCH(TRUE,H14="North",10000,H14="South",10000,5000)} -> 10000 | K14: Pending | L14: 0 | M14: Mobile | N14: =RANDBETWEEN(0,10) -> 9 | O14: Kickstarting Web Dev | P14: BE / BTech - CS / IT
A15: 64601 | B15: Manya Malik | C15: Female | D15: =IF(C15="Male","Mr.","Mrs.") -> Mrs. | E15: =_xlfn.CONCAT(D15,B15) -> Mrs.Manya Malik | F15: =LEFT(B15,FIND(" ",B15)-1) -> Manya | G15: =MID(B15,FIND(" ",B15)+1,LEN(B15)) -> Malik | H15: North | I15: 2021 | J15: {=_xlfn.SWITCH(TRUE,H15="North",10000,H15="South",10000,5000)} -> 10000 | K15: Pending | L15: 389 | M15: Mobile | N15: 70 | O15: Kickstarting Web Dev | P15: Non-Coding, Non Engineering
A16: 64602 | B16: Laksh Dutta | C16: Male | D16: =IF(C16="Male","Mr.","Mrs.") -> Mr. | E16: =_xlfn.CONCAT(D16,B16) -> Mr.Laksh Dutta | F16: =LEFT(B16,FIND(" ",B16)-1) -> Laksh | G16: =MID(B16,FIND(" ",B16)+1,LEN(B16)) -> Dutta | H16: North | I16: 2026 | J16: {=_xlfn.SWITCH(TRUE,H16="North",10000,H16="South",10000,5000)} -> 10000 | K16: Completed | L16: 1660 | M16: Mobile | N16: 18 | O16: Data Structure and Algorithms | P16: Non-Coding, Non Engineering
A17: 64603 | B17: Aaradhya Sharma | C17: Female | D17: =IF(C17="Male","Mr.","Mrs.") -> Mrs. | E17: =_xlfn.CONCAT(D17,B17) -> Mrs.Aaradhya Sharma | F17: =LEFT(B17,FIND(" ",B17)-1) -> Aaradhya | G17: =MID(B17,FIND(" ",B17)+1,LEN(B17)) -> Sharma | H17: East | I17: 2023 | J17: {=_xlfn.SWITCH(TRUE,H17="North",10000,H17="South",10000,5000)} -> 5000 | K17: Pending | L17: 0 | M17: Mobile | N17: 50 | O17: Kickstarting Web Dev | P17: Non-Coding, Non Engineering
A18: 64604 | B18: Ira Joshi | C18: Female | D18: =IF(C18="Male","Mr.","Mrs.") -> Mrs. | E18: =_xlfn.CONCAT(D18,B18) -> Mrs.Ira Joshi | F18: =LEFT(B18,FIND(" ",B18)-1) -> Ira | G18: =MID(B18,FIND(" ",B18)+1,LEN(B18)) -> Joshi | H18: East | I18: 2026 | J18: {=_xlfn.SWITCH(TRUE,H18="North",10000,H18="South",10000,5000)} -> 5000 | K18: Pending | L18: 250 | M18: Mobile | N18: =RANDBETWEEN(0,10) -> 7 | O18: Data Structure and Algorithms | P18: BE / BTech - CS / IT
A19: 64605 | B19: Samarth Nair | C19: Male | D19: =IF(C19="Male","Mr.","Mrs.") -> Mr. | E19: =_xlfn.CONCAT(D19,B19) -> Mr.Samarth Nair | F19: =LEFT(B19,FIND(" ",B19)-1) -> Samarth | G19: =MID(B19,FIND(" ",B19)+1,LEN(B19)) -> Nair | H19: South | I19: 2017 | J19: {=_xlfn.SWITCH(TRUE,H19="North",10000,H19="South",10000,5000)} -> 10000 | K19: Completed | L19: 4902 | M19: Web | N19: 21 | O19: Competitive Coding | P19: BE / BTech - CS / IT
A20: 64606 | B20: Sai Singh | C20: Male | D20: =IF(C20="Male","Mr.","Mrs.") -> Mr. | E20: =_xlfn.CONCAT(D20,B20) -> Mr.Sai Singh | F20: =LEFT(B20,FIND(" ",B20)-1) -> Sai | G20: =MID(B20,FIND(" ",B20)+1,LEN(B20)) -> Singh | H20: East | I20: 2026 | J20: {=_xlfn.SWITCH(TRUE,H20="North",10000,H20="South",10000,5000)} -> 5000 | K20: Completed | L20: 2589 | M20: Mobile | N20: =RANDBETWEEN(0,10) -> 7 | O20: Data Structure and Algorithms | P20: Non-Coding, Non Engineering
A21: 64607 | B21: Dev Sharma | C21: Male | D21: =IF(C21="Male","Mr.","Mrs.") -> Mr. | E21: =_xlfn.CONCAT(D21,B21) -> Mr.Dev Sharma | F21: =LEFT(B21,FIND(" ",B21)-1) -> Dev | G21: =MID(B21,FIND(" ",B21)+1,LEN(B21)) -> Sharma | H21: North | I21: 2025 | J21: {=_xlfn.SWITCH(TRUE,H21="North",10000,H21="South",10000,5000)} -> 10000 | K21: Pending | L21: 0 | M21: Mobile | N21: =RANDBETWEEN(0,10) -> 8 | O21: Kickstarting Web Dev | P21: Non-Coding, Non Engineering
A22: 64608 | B22: Vihaan Pillai | C22: Male | D22: =IF(C22="Male","Mr.","Mrs.") -> Mr. | E22: =_xlfn.CONCAT(D22,B22) -> Mr.Vihaan Pillai | F22: =LEFT(B22,FIND(" ",B22)-1) -> Vihaan | G22: =MID(B22,FIND(" ",B22)+1,LEN(B22)) -> Pillai | H22: North | I22: 2024 | J22: {=_xlfn.SWITCH(TRUE,H22="North",10000,H22="South",10000,5000)} -> 10000 | K22: Pending | L22: 424 | M22: Mobile | N22: 54 | O22: Competitive Coding | P22: BCA / MCA
A23: 64609 | B23: Manya Pillai | C23: Female | D23: =IF(C23="Male","Mr.","Mrs.") -> Mrs. | E23: =_xlfn.CONCAT(D23,B23) -> Mrs.Manya Pillai | F23: =LEFT(B23,FIND(" ",B23)-1) -> Manya | G23: =MID(B23,FIND(" ",B23)+1,LEN(B23)) -> Pillai | H23: North | I23: 2021 | J23: {=_xlfn.SWITCH(TRUE,H23="North",10000,H23="South",10000,5000)} -> 10000 | K23: Pending | L23: 0 | M23: Mobile | N23: 33 | O23: Kickstarting Web Dev | P23: Non-Coding, Non Engineering
A24: 64610 | B24: Om Thakur | C24: Male | D24: =IF(C24="Male","Mr.","Mrs.") -> Mr. | E24: =_xlfn.CONCAT(D24,B24) -> Mr.Om Thakur | F24: =LEFT(B24,FIND(" ",B24)-1) -> Om | G24: =MID(B24,FIND(" ",B24)+1,LEN(B24)) -> Thakur | H24: North | I24: 2023 | J24: {=_xlfn.SWITCH(TRUE,H24="North",10000,H24="South",10000,5000)} -> 10000 | K24: Completed | L24: 18697 | M24: Web | N24: 16 | O24: Competitive Coding | P24: Non-Coding, Non Engineering
A25: 64611 | B25: Naira Rao | C25: Female | D25: =IF(C25="Male","Mr.","Mrs.") -> Mrs. | E25: =_xlfn.CONCAT(D25,B25) -> Mrs.Naira Rao | F25: =LEFT(B25,FIND(" ",B25)-1) -> Naira | G25: =MID(B25,FIND(" ",B25)+1,LEN(B25)) -> Rao | H25: West | I25: 2023 | J25: {=_xlfn.SWITCH(TRUE,H25="North",10000,H25="South",10000,5000)} -> 5000 | K25: Pending | L25: 0 | M25: Mobile | N25: 47 | O25: Kickstarting Web Dev | P25: BE / BTech - CS / IT
A26: 64612 | B26: Aarohi Reddy | C26: Female | D26: =IF(C26="Male","Mr.","Mrs.") -> Mrs. | E26: =_xlfn.CONCAT(D26,B26) -> Mrs.Aarohi Reddy | F26: =LEFT(B26,FIND(" ",B26)-1) -> Aarohi | G26: =MID(B26,FIND(" ",B26)+1,LEN(B26)) -> Reddy | H26: North | I26: 2022 | J26: {=_xlfn.SWITCH(TRUE,H26="North",10000,H26="South",10000,5000)} -> 10000 | K26: Pending | L26: 0 | M26: Mobile | N26: 65 | O26: Kickstarting Web Dev | P26: Non-Coding, Non Engineering
A27: 64613 | B27: Anvi Verma | C27: Female | D27: =IF(C27="Male","Mr.","Mrs.") -> Mrs. | E27: =_xlfn.CONCAT(D27,B27) -> Mrs.Anvi Verma | F27: =LEFT(B27,FIND(" ",B27)-1) -> Anvi | G27: =MID(B27,FIND(" ",B27)+1,LEN(B27)) -> Verma | H27: West | I27: 2025 | J27: {=_xlfn.SWITCH(TRUE,H27="North",10000,H27="South",10000,5000)} -> 5000 | K27: Pending | L27: 0 | M27: Mobile | N27: 46 | O27: Kickstarting Web Dev | P27: BCA / MCA
A28: 64614 | B28: Tara Sinha | C28: Female | D28: =IF(C28="Male","Mr.","Mrs.") -> Mrs. | E28: =_xlfn.CONCAT(D28,B28) -> Mrs.Tara Sinha | F28: =LEFT(B28,FIND(" ",B28)-1) -> Tara | G28: =MID(B28,FIND(" ",B28)+1,LEN(B28)) -> Sinha | H28: South | I28: 2026 | J28: {=_xlfn.SWITCH(TRUE,H28="North",10000,H28="South",10000,5000)} -> 10000 | K28: Pending | L28: 0 | M28: Mobile | N28: =RANDBETWEEN(0,10) -> 3 | O28: Kickstarting Web Dev | P28: BE / BTech - Non CS / IT
A29: 64618 | B29: Vihaan Jain | C29: Male | D29: =IF(C29="Male","Mr.","Mrs.") -> Mr. | E29: =_xlfn.CONCAT(D29,B29) -> Mr.Vihaan Jain | F29: =LEFT(B29,FIND(" ",B29)-1) -> Vihaan | G29: =MID(B29,FIND(" ",B29)+1,LEN(B29)) -> Jain | H29: West | I29: 2023 | J29: {=_xlfn.SWITCH(TRUE,H29="North",10000,H29="South",10000,5000)} -> 5000 | K29: Pending | L29: 0 | M29: Mobile | N29: 55 | O29: Kickstarting Web Dev | P29: BE / BTech - CS / IT
A30: 64619 | B30: Diya Sharma | C30: Female | D30: =IF(C30="Male","Mr.","Mrs.") -> Mrs. | E30: =_xlfn.CONCAT(D30,B30) -> Mrs.Diya Sharma | F30: =LEFT(B30,FIND(" ",B30)-1) -> Diya | G30: =MID(B30,FIND(" ",B30)+1,LEN(B30)) -> Sharma | H30: South | I30: 2026 | J30: {=_xlfn.SWITCH(TRUE,H30="North",10000,H30="South",10000,5000)} -> 10000 | K30: Completed | L30: 12779 | M30: Mobile | N30: 75 | O30: Kickstarting Web Dev | P30: BE / BTech - CS / IT
A31: 64620 | B31: Vivaan Reddy | C31: Male | D31: =IF(C31="Male","Mr.","Mrs.") -> Mr. | E31: =_xlfn.CONCAT(D31,B31) -> Mr.Vivaan Reddy | F31: =LEFT(B31,FIND(" ",B31)-1) -> Vivaan | G31: =MID(B31,FIND(" ",B31)+1,LEN(B31)) -> Reddy | H31: North | I31: 2023 | J31: {=_xlfn.SWITCH(TRUE,H31="North",10000,H31="South",10000,5000)} -> 10000 | K31: Pending | L31: 265 | M31: Mobile | N31: 28 | O31: Data Structure and Algorithms | P31: BE / BTech - CS / IT
A32: 64621 | B32: Saanvi Naidu | C32: Female | D32: =IF(C32="Male","Mr.","Mrs.") -> Mrs. | E32: =_xlfn.CONCAT(D32,B32) -> Mrs.Saanvi Naidu | F32: =LEFT(B32,FIND(" ",B32)-1) -> Saanvi | G32: =MID(B32,FIND(" ",B32)+1,LEN(B32)) -> Naidu | H32: East | I32: 2025 | J32: {=_xlfn.SWITCH(TRUE,H32="North",10000,H32="South",10000,5000)} -> 5000 | K32: Pending | L32: 0 | M32: Mobile | N32: =RANDBETWEEN(0,10) -> 2 | O32: Kickstarting Web Dev | P32: Non-Coding, Non Engineering
A33: 64622 | B33: Riddhi Malik | C33: Female | D33: =IF(C33="Male","Mr.","Mrs.") -> Mrs. | E33: =_xlfn.CONCAT(D33,B33) -> Mrs.Riddhi Malik | F33: =LEFT(B33,FIND(" ",B33)-1) -> Riddhi | G33: =MID(B33,FIND(" ",B33)+1,LEN(B33)) -> Malik | H33: North | I33: 2024 | J33: {=_xlfn.SWITCH(TRUE,H33="North",10000,H33="South",10000,5000)} -> 10000 | K33: Completed | L33: 9147 | M33: Mobile | N33: 60 | O33: Kickstarting Web Dev | P33: Non-Coding, Non Engineering
A34: 64624 | B34: Aaryan Bhatt | C34: Male | D34: =IF(C34="Male","Mr.","Mrs.") -> Mr. | E34: =_xlfn.CONCAT(D34,B34) -> Mr.Aaryan Bhatt | F34: =LEFT(B34,FIND(" ",B34)-1) -> Aaryan | G34: =MID(B34,FIND(" ",B34)+1,LEN(B34)) -> Bhatt | H34: East | I34: 2019 | J34: {=_xlfn.SWITCH(TRUE,H34="North",10000,H34="South",10000,5000)} -> 5000 | K34: Payment in Process | L34: 0 | M34: Mobile | N34: 64 | O34: Data Structure and Algorithms | P34: Non-Coding, Non Engineering
A35: 64625 | B35: Charvi Bhatt | C35: Female | D35: =IF(C35="Male","Mr.","Mrs.") -> Mrs. | E35: =_xlfn.CONCAT(D35,B35) -> Mrs.Charvi Bhatt | F35: =LEFT(B35,FIND(" ",B35)-1) -> Charvi | G35: =MID(B35,FIND(" ",B35)+1,LEN(B35)) -> Bhatt | H35: South | I35: 2026 | J35: {=_xlfn.SWITCH(TRUE,H35="North",10000,H35="South",10000,5000)} -> 10000 | K35: Completed | L35: 6964 | M35: Mobile | N35: 62 | O35: Data Structure and Algorithms | P35: Non-Coding, Non Engineering
A36: 64626 | B36: Aryan Nair | C36: Male | D36: =IF(C36="Male","Mr.","Mrs.") -> Mr. | E36: =_xlfn.CONCAT(D36,B36) -> Mr.Aryan Nair | F36: =LEFT(B36,FIND(" ",B36)-1) -> Aryan | G36: =MID(B36,FIND(" ",B36)+1,LEN(B36)) -> Nair | H36: East | I36: 2022 | J36: {=_xlfn.SWITCH(TRUE,H36="North",10000,H36="South",10000,5000)} -> 5000 | K36: Completed | L36: 10827 | M36: Mobile | N36: 29 | O36: Data Structure and Algorithms | P36: BCA / MCA
A37: 64627 | B37: Aaryan Kumar | C37: Male | D37: =IF(C37="Male","Mr.","Mrs.") -> Mr. | E37: =_xlfn.CONCAT(D37,B37) -> Mr.Aaryan Kumar | F37: =LEFT(B37,FIND(" ",B37)-1) -> Aaryan | G37: =MID(B37,FIND(" ",B37)+1,LEN(B37)) -> Kumar | H37: West | I37: 2024 | J37: {=_xlfn.SWITCH(TRUE,H37="North",10000,H37="South",10000,5000)} -> 5000 | K37: Pending | L37: 0 | M37: Mobile | N37: 49 | O37: Data Structure and Algorithms | P37: Non-Coding, Non Engineering
A38: 64628 | B38: Samarth Kapoor | C38: Male | D38: =IF(C38="Male","Mr.","Mrs.") -> Mr. | E38: =_xlfn.CONCAT(D38,B38) -> Mr.Samarth Kapoor | F38: =LEFT(B38,FIND(" ",B38)-1) -> Samarth | G38: =MID(B38,FIND(" ",B38)+1,LEN(B38)) -> Kapoor | H38: West | I38: 2021 | J38: {=_xlfn.SWITCH(TRUE,H38="North",10000,H38="South",10000,5000)} -> 5000 | K38: Pending | L38: 0 | M38: Mobile | N38: 14 | O38: Data Structure and Algorithms | P38: BCA / MCA
A39: 64629 | B39: Gauri Chopra | C39: Female | D39: =IF(C39="Male","Mr.","Mrs.") -> Mrs. | E39: =_xlfn.CONCAT(D39,B39) -> Mrs.Gauri Chopra | F39: =LEFT(B39,FIND(" ",B39)-1) -> Gauri | G39: =MID(B39,FIND(" ",B39)+1,LEN(B39)) -> Chopra | H39: West | I39: 2024 | J39: {=_xlfn.SWITCH(TRUE,H39="North",10000,H39="South",10000,5000)} -> 5000 | K39: Completed | L39: 24189 | M39: Web | N39: 67 | O39: Competitive Coding | P39: BE / BTech - CS / IT
A40: 64630 | B40: Vivaan Singh | C40: Male | D40: =IF(C40="Male","Mr.","Mrs.") -> Mr. | E40: =_xlfn.CONCAT(D40,B40) -> Mr.Vivaan Singh | F40: =LEFT(B40,FIND(" ",B40)-1) -> Vivaan | G40: =MID(B40,FIND(" ",B40)+1,LEN(B40)) -> Singh | H40: South | I40: 2018 | J40: {=_xlfn.SWITCH(TRUE,H40="North",10000,H40="South",10000,5000)} -> 10000 | K40: Pending | L40: 4106 | M40: Web | N40: 54 | O40: Competitive Coding | P40: BCA / MCA
...

Sheet Login Issues
A1: User ID | B1: Device | C1: Name | D1: Region
A2: 64633 | B2: =_xlfn.XLOOKUP(A2,Data!$A$2:$A$1001,Data!$M$2:$M$1001) -> Mobile | C2: =_xlfn.XLOOKUP(A2,Data!A2:A1001,Data!E2:E1001) -> Mr.Laksh Kulkarni | D2: =_xlfn.XLOOKUP(A2,Data!A2:A1001,Data!H2:H1001) -> South
A3: 64634 | B3: =_xlfn.XLOOKUP(A3,Data!$A$2:$A$1001,Data!$M$2:$M$1001) -> Mobile | C3: =_xlfn.XLOOKUP(A3,Data!A3:A1002,Data!E3:E1002) -> Mr.Atharv Singh | D3: =_xlfn.XLOOKUP(A3,Data!A3:A1002,Data!H3:H1002) -> North
A4: 64972 | B4: =_xlfn.XLOOKUP(A4,Data!$A$2:$A$1001,Data!$M$2:$M$1001) -> Mobile | C4: =_xlfn.XLOOKUP(A4,Data!A4:A1003,Data!E4:E1003) -> Mrs.Anaya Kumar | D4: =_xlfn.XLOOKUP(A4,Data!A4:A1003,Data!H4:H1003) -> East
A5: 64805 | B5: =_xlfn.XLOOKUP(A5,Data!$A$2:$A$1001,Data!$M$2:$M$1001) -> Mobile | C5: =_xlfn.XLOOKUP(A5,Data!A5:A1004,Data!E5:E1004) -> Mrs.Tara Patel | D5: =_xlfn.XLOOKUP(A5,Data!A5:A1004,Data!H5:H1004) -> North
A6: 64637 | B6: =_xlfn.XLOOKUP(A6,Data!$A$2:$A$1001,Data!$M$2:$M$1001) -> Mobile | C6: =_xlfn.XLOOKUP(A6,Data!A6:A1005,Data!E6:E1005) -> Mrs.Aarohi Gupta | D6: =_xlfn.XLOOKUP(A6,Data!A6:A1005,Data!H6:H1005) -> North
A7: 64806 | B7: =_xlfn.XLOOKUP(A7,Data!$A$2:$A$1001,Data!$M$2:$M$1001) -> Mobile | C7: =_xlfn.XLOOKUP(A7,Data!A7:A1006,Data!E7:E1006) -> Mrs.Eva Verma | D7: =_xlfn.XLOOKUP(A7,Data!A7:A1006,Data!H7:H1006) -> East
A8: 64970 | B8: =_xlfn.XLOOKUP(A8,Data!$A$2:$A$1001,Data!$M$2:$M$1001) -> Mobile | C8: =_xlfn.XLOOKUP(A8,Data!A8:A1007,Data!E8:E1007) -> Mrs.Anvi Dutta | D8: =_xlfn.XLOOKUP(A8,Data!A8:A1007,Data!H8:H1007) -> South
A9: 64971 | B9: =_xlfn.XLOOKUP(A9,Data!$A$2:$A$1001,Data!$M$2:$M$1001) -> Mobile | C9: =_xlfn.XLOOKUP(A9,Data!A9:A1008,Data!E9:E1008) -> Mr.Dhanush Sinha | D9: =_xlfn.XLOOKUP(A9,Data!A9:A1008,Data!H9:H1008) -> West
A10: 65201 | B10: =_xlfn.XLOOKUP(A10,Data!$A$2:$A$1001,Data!$M$2:$M$1001) -> Mobile | C10: =_xlfn.XLOOKUP(A10,Data!A10:A1009,Data!E10:E1009) -> Mrs.Aaradhya Das | D10: =_xlfn.XLOOKUP(A10,Data!A10:A1009,Data!H10:H1009) -> West
A11: 65202 | B11: =_xlfn.XLOOKUP(A11,Data!$A$2:$A$1001,Data!$M$2:$M$1001) -> Mobile | C11: =_xlfn.XLOOKUP(A11,Data!A11:A1010,Data!E11:E1010) -> Mrs.Sara Sharma | D11: =_xlfn.XLOOKUP(A11,Data!A11:A1010,Data!H11:H1010) -> West

Sheet Analysis

Sheet KPIs and Pivot Table
B3: =SUM(Data!J2:J1001) -> 8015000 | C3: =SUMIF(Data!K2:K1001,"=Completed",Data!J2:J1001) -> 2630000 | D3: =AVERAGE(Data!N2:N1001) -> 31.576 | E3: =AVERAGE(Data!L2:L1001) -> 4356.089 | F3: =COUNTIF(Data!K2:K1001,"=Completed") -> 327 | G3: =F3/H3 -> 0.327 | H3: =COUNT(Data!A2:A1001) -> 1000 | I3: =COUNTIF(Data!M2:M1001,"=Mobile")/H3 -> 0.772 | J3: =B3/H3 -> 8015
B7: Region | C7: Students enrolled | E7: Signup Device | F7: Students enrolled | H7: Course Name | I7: Count of ID
B8: North | C8: 344 | E8: Mobile | F8: 772 | H8: Competitive Coding | I8: 511
B9: South | C9: 259 | E9: Tablet | F9: 7 | H9: Data Structure and Algorithms | I9: 470
B10: East | C10: 205 | E10: Web | F10: 221 | H10: Kickstarting Web Dev | I10: 19
B11: West | C11: 192
B13: DegreeCategories - DegreeCategoryId → Name | C13: Count of ID | E13: PassingYear | F13: Count of ID | H13: Streak | I13: Count of ID
B14: BCA / MCA | C14: 148 | E14: 2002-2006 | F14: 4 | H14: 0-9 | I14: 308
B15: BE / BTech - CS / IT | C15: 354 | E15: 2007-2011 | F15: 1 | H15: 10-19 | I15: 98
B16: BE / BTech - Non CS / IT | C16: 172 | E16: 2012-2016 | F16: 28 | H16: 20-29 | I16: 104
B17: Diploma | C17: 109 | E17: 2017-2021 | F17: 194 | H17: 30-39 | I17: 114
B18: Non-Coding, Non Engineering | C18: 217 | E18: 2022-2026 | F18: 650 | H18: 40-49 | I18: 94
E19: 2027-2031 | F19: 123 | H19: 50-59 | I19: 93
H20: 60-69 | I20: 102
H21: 70-80 | I21: 87
